<?xml version="1.0" encoding="utf-8"?>
<!-- This URDF was automatically created by SolidWorks to URDF Exporter! Originally created by Stephen Brawner (brawner@gmail.com) 
     Commit Version: 1.6.0-4-g7f85cfe  Build Version: 1.6.7995.38578
     For more information, please see http://wiki.ros.org/sw_urdf_exporter -->
<robot
  name="medium_jxb_urdf">
  <link
    name="middle_base_link">
    <inertial>
      <origin
        xyz="-3.50835464926744E-18 0 0.1575"
        rpy="0 0 0" />
      <mass
        value="6.86150224922301" />
      <inertia
        ixx="0.112314214941969"
        ixy="0"
        ixz="-1.89583913414277E-34"
        iyy="0.112314214941969"
        iyz="-3.75910630851091E-34"
        izz="0.111156336437413" />
    </inertial>
    <visual>
      <origin
        xyz="0 0 0"
        rpy="0 0 0" />
      <geometry>
        <mesh
          filename="./meshes/middle_base_link.STL" />
      </geometry>
      <material
        name="">
        <color
          rgba="0.698039215686274 0.698039215686274 0.698039215686274 1" />
      </material>
    </visual>
    <collision>
      <origin
        xyz="0 0 0"
        rpy="0 0 0" />
      <geometry>
        <mesh
          filename="./meshes/middle_base_link.STL" />
      </geometry>
    </collision>
  </link>
  <link
    name="middlelink1">
    <inertial>
      <origin
        xyz="1.72452213357314E-07 -0.029507839330969 -0.024488249708855"
        rpy="0 0 0" />
      <mass
        value="7.20562768329708" />
      <inertia
        ixx="0.124309849843595"
        ixy="-1.82446758835654E-08"
        ixz="-2.62017032728461E-08"
        iyy="0.120303135134466"
        iyz="0.0141924165130043"
        izz="0.123436994569792" />
    </inertial>
    <visual>
      <origin
        xyz="0 0 0"
        rpy="0 0 0" />
      <geometry>
        <mesh
          filename="./meshes/middlelink1.STL" />
      </geometry>
      <material
        name="">
        <color
          rgba="0.698039215686274 0.698039215686274 0.698039215686274 1" />
      </material>
    </visual>
    <collision>
      <origin
        xyz="0 0 0"
        rpy="0 0 0" />
      <geometry>
        <mesh
          filename="./meshes/middlelink1.STL" />
      </geometry>
    </collision>
  </link>
  <joint
    name="middlejoint1"
    type="revolute">
    <origin
      xyz="0 0 0.495"
      rpy="0 0 3.1416" />
    <parent
      link="middle_base_link" />
    <child
      link="middlelink1" />
    <axis
      xyz="0 0 1" />
    <limit
      lower="-2.09"
      upper="2.09"
      effort="400"
      velocity="0.05" />
  </joint>
  <link
    name="middlelink2">
    <inertial>
      <origin
        xyz="-1.72452213453855E-07 -0.0244882497088551 -0.0295078393309687"
        rpy="0 0 0" />
      <mass
        value="7.20562768329708" />
      <inertia
        ixx="0.124309849843595"
        ixy="2.62017032813595E-08"
        ixz="1.8244675871022E-08"
        iyy="0.123436994569792"
        iyz="0.0141924165130043"
        izz="0.120303135134466" />
    </inertial>
    <visual>
      <origin
        xyz="0 0 0"
        rpy="0 0 0" />
      <geometry>
        <mesh
          filename="./meshes/middlelink2.STL" />
      </geometry>
      <material
        name="">
        <color
          rgba="0.698039215686274 0.698039215686274 0.698039215686274 1" />
      </material>
    </visual>
    <collision>
      <origin
        xyz="0 0 0"
        rpy="0 0 0" />
      <geometry>
        <mesh
          filename="./meshes/middlelink2.STL" />
      </geometry>
    </collision>
  </link>
  <joint
    name="middlejoint2"
    type="revolute">
    <origin
      xyz="0 -0.378 0"
      rpy="1.5708 3.14 0" />
    <parent
      link="middlelink1" />
    <child
      link="middlelink2" />
    <axis
      xyz="0 0 1" />
    <limit
      lower="-2.09"
      upper="2.09"
      effort="400"
      velocity="0.05" />
  </joint>
  <link
    name="middlelink3">
    <inertial>
      <origin
        xyz="1.01250002316641 -3.05141198975178E-06 -4.0423342199114E-06"
        rpy="0 0 0" />
      <mass
        value="51.2645196188042" />
      <inertia
        ixx="0.874218249343095"
        ixy="6.82319933723215E-06"
        ixz="-0.564970164921232"
        iyy="23.6299179465577"
        iyz="-2.0960756109822E-05"
        izz="23.5916216342004" />
    </inertial>
    <visual>
      <origin
        xyz="0 0 0"
        rpy="0 0 0" />
      <geometry>
        <mesh
          filename="./meshes/middlelink3.STL" />
      </geometry>
      <material
        name="">
        <color
          rgba="0.698039215686274 0.698039215686274 0.698039215686274 1" />
      </material>
    </visual>
    <collision>
      <origin
        xyz="0 0 0"
        rpy="0 0 0" />
      <geometry>
        <mesh
          filename="./meshes/middlelink3.STL" />
      </geometry>
    </collision>
  </link>
  <joint
    name="middlejoint3"
    type="revolute">
    <origin
      xyz="0 -0.3825 0"
      rpy="1.5708 -1.5708 0" />
    <parent
      link="middlelink2" />
    <child
      link="middlelink3" />
    <axis
      xyz="0 0 1" />
    <limit
      lower="-2.09"
      upper="2.09"
      effort="400"
      velocity="0.05" />
  </joint>
  <link
    name="middlelink4">
    <inertial>
      <origin
        xyz="1.0125 -3.0514E-06 4.0423E-06"
        rpy="0 0 0" />
      <mass
        value="51.265" />
      <inertia
        ixx="0.87422"
        ixy="-6.8232E-06"
        ixz="-0.56497"
        iyy="23.63"
        iyz="2.0961E-05"
        izz="23.592" />
    </inertial>
    <visual>
      <origin
        xyz="0 0 0"
        rpy="0 0 0" />
      <geometry>
        <mesh
          filename="./meshes/middlelink4.STL" />
      </geometry>
      <material
        name="">
        <color
          rgba="0.69804 0.69804 0.69804 1" />
      </material>
    </visual>
    <collision>
      <origin
        xyz="0 0 0"
        rpy="0 0 0" />
      <geometry>
        <mesh
          filename="./meshes/middlelink4.STL" />
      </geometry>
    </collision>
  </link>
  <joint
    name="middlejoint4"
    type="revolute">
    <origin
      xyz="2.025 0 0.405"
      rpy="0 0 -3.1416" />
    <parent
      link="middlelink3" />
    <child
      link="middlelink4" />
    <axis
      xyz="0 0 1" />
    <limit
      lower="-4.2"
      upper="4.2"
      effort="400"
      velocity="0.05" />
  </joint>
  <link
    name="middlelink5">
    <inertial>
      <origin
        xyz="1.72452213509366E-07 -0.0295078393309691 -0.024488249708855"
        rpy="0 0 0" />
      <mass
        value="7.20562768329708" />
      <inertia
        ixx="0.124309849843595"
        ixy="-1.8244675862307E-08"
        ixz="-2.6201703247966E-08"
        iyy="0.120303135134465"
        iyz="0.0141924165130043"
        izz="0.123436994569792" />
    </inertial>
    <visual>
      <origin
        xyz="0 0 0"
        rpy="0 0 0" />
      <geometry>
        <mesh
          filename="./meshes/middlelink5.STL" />
      </geometry>
      <material
        name="">
        <color
          rgba="0.698039215686274 0.698039215686274 0.698039215686274 1" />
      </material>
    </visual>
    <collision>
      <origin
        xyz="0 0 0"
        rpy="0 0 0" />
      <geometry>
        <mesh
          filename="./meshes/middlelink5.STL" />
      </geometry>
    </collision>
  </link>
  <joint
    name="middlejoint5"
    type="revolute">
    <origin
      xyz="2.025 0 0.3825"
      rpy="0 0 1.5708" />
    <parent
      link="middlelink4" />
    <child
      link="middlelink5" />
    <axis
      xyz="0 0 1" />
    <limit
      lower="-2.09"
      upper="2.09"
      effort="400"
      velocity="0.05" />
  </joint>
  <link
    name="middlelink6">
    <inertial>
      <origin
        xyz="-1.7245E-07 -0.024488 -0.029508"
        rpy="0 0 0" />
      <mass
        value="7.2056" />
      <inertia
        ixx="0.12431"
        ixy="2.6202E-08"
        ixz="1.8245E-08"
        iyy="0.12344"
        iyz="0.014192"
        izz="0.1203" />
    </inertial>
    <visual>
      <origin
        xyz="0 0 0"
        rpy="0 0 0" />
      <geometry>
        <mesh
          filename="./meshes/middlelink6.STL" />
      </geometry>
      <material
        name="">
        <color
          rgba="0.69804 0.69804 0.69804 1" />
      </material>
    </visual>
    <collision>
      <origin
        xyz="0 0 0"
        rpy="0 0 0" />
      <geometry>
        <mesh
          filename="./meshes/middlelink6.STL" />
      </geometry>
    </collision>
  </link>
  <joint
    name="middlejoint6"
    type="revolute">
    <origin
      xyz="0 -0.378 0"
      rpy="1.5708 -3.14 0" />
    <parent
      link="middlelink5" />
    <child
      link="middlelink6" />
    <axis
      xyz="0 0 1" />
    <limit
      lower="-2.09"
      upper="2.09"
      effort="400"
      velocity="0.05" />
  </joint>
  <link
    name="middlelink7">
    <inertial>
      <origin
        xyz="0 2.6229E-17 -0.1575"
        rpy="0 0 0" />
      <mass
        value="6.8615" />
      <inertia
        ixx="0.11231"
        ixy="-9.2174E-29"
        ixz="-3.8979E-18"
        iyy="0.11231"
        iyz="1.9283E-19"
        izz="0.11116" />
    </inertial>
    <visual>
      <origin
        xyz="0 0 0"
        rpy="0 0 0" />
      <geometry>
        <mesh
          filename="./meshes/middlelink7.STL" />
      </geometry>
      <material
        name="">
        <color
          rgba="0.69804 0.69804 0.69804 1" />
      </material>
    </visual>
    <collision>
      <origin
        xyz="0 0 0"
        rpy="0 0 0" />
      <geometry>
        <mesh
          filename="./meshes/middlelink7.STL" />
      </geometry>
    </collision>
  </link>
  <joint
    name="middlejoint7"
    type="revolute">
    <origin
      xyz="0 -0.495 0"
      rpy="-1.5708 3.14 3.1416" />
    <parent
      link="middlelink6" />
    <child
      link="middlelink7" />
    <axis
      xyz="0 0 1" />
    <limit
      lower="-2.09"
      upper="2.09"
      effort="400"
      velocity="0.05" />
  </joint>
</robot>